[2022-11-02 13:32:26 +0300] [4114] [INFO] Starting gunicorn 20.1.0
[2022-11-02 13:32:26 +0300] [4114] [INFO] Listening at: http://127.0.0.1:8001 (4114)
[2022-11-02 13:32:26 +0300] [4114] [INFO] Using worker: sync
[2022-11-02 13:32:26 +0300] [4118] [INFO] Booting worker with pid: 4118
[2022-11-02 13:32:27 +0300] [4120] [INFO] Booting worker with pid: 4120
[2022-11-02 13:32:27 +0300] [4122] [INFO] Booting worker with pid: 4122
[2022-11-02 13:32:52 +0300] [4114] [INFO] Handling signal: int
[2022-11-02 10:32:52 +0000] [4118] [INFO] Worker exiting (pid: 4118)
[2022-11-02 10:32:52 +0000] [4120] [INFO] Worker exiting (pid: 4120)
[2022-11-02 10:32:52 +0000] [4122] [INFO] Worker exiting (pid: 4122)
[2022-11-02 13:32:52 +0300] [4114] [INFO] Shutting down: Master
[2022-11-02 13:34:14 +0300] [4176] [INFO] Starting gunicorn 20.1.0
[2022-11-02 13:34:14 +0300] [4176] [INFO] Listening at: http://127.0.0.1:8001 (4176)
[2022-11-02 13:34:14 +0300] [4176] [INFO] Using worker: sync
[2022-11-02 13:34:14 +0300] [4178] [INFO] Booting worker with pid: 4178
[2022-11-02 13:34:14 +0300] [4179] [INFO] Booting worker with pid: 4179
[2022-11-02 13:34:14 +0300] [4180] [INFO] Booting worker with pid: 4180
[2022-11-02 13:34:22 +0300] [4176] [INFO] Handling signal: int
[2022-11-02 10:34:22 +0000] [4180] [INFO] Worker exiting (pid: 4180)
[2022-11-02 10:34:22 +0000] [4179] [INFO] Worker exiting (pid: 4179)
[2022-11-02 10:34:22 +0000] [4178] [INFO] Worker exiting (pid: 4178)
[2022-11-02 13:34:22 +0300] [4176] [INFO] Shutting down: Master
[2022-11-02 13:34:52 +0300] [4226] [INFO] Starting gunicorn 20.1.0
[2022-11-02 13:34:52 +0300] [4226] [ERROR] Retrying in 1 second.
[2022-11-02 13:34:53 +0300] [4226] [ERROR] Retrying in 1 second.
[2022-11-02 13:34:54 +0300] [4226] [ERROR] Retrying in 1 second.
[2022-11-02 13:34:55 +0300] [4226] [ERROR] Retrying in 1 second.
[2022-11-02 13:34:56 +0300] [4226] [ERROR] Retrying in 1 second.
[2022-11-02 13:34:57 +0300] [4226] [ERROR] Can't connect to ('/home/admsys/djangotest/gunicorn/gunicorn.sock', 8000)
[2022-11-02 13:34:58 +0300] [4242] [INFO] Starting gunicorn 20.1.0
[2022-11-02 13:34:58 +0300] [4242] [ERROR] Retrying in 1 second.
[2022-11-02 13:34:59 +0300] [4242] [ERROR] Retrying in 1 second.
[2022-11-02 13:35:00 +0300] [4242] [ERROR] Retrying in 1 second.
[2022-11-02 13:35:01 +0300] [4242] [ERROR] Retrying in 1 second.
[2022-11-02 13:35:02 +0300] [4242] [ERROR] Retrying in 1 second.
[2022-11-02 13:35:03 +0300] [4242] [ERROR] Can't connect to ('/home/admsys/djangotest/gunicorn/gunicorn.sock', 8000)
[2022-11-02 13:35:04 +0300] [4273] [INFO] Starting gunicorn 20.1.0
[2022-11-02 13:35:04 +0300] [4273] [INFO] Listening at: http://127.0.0.1:8001 (4273)
[2022-11-02 13:35:04 +0300] [4273] [INFO] Using worker: sync
[2022-11-02 13:35:04 +0300] [4275] [INFO] Booting worker with pid: 4275
[2022-11-02 13:35:04 +0300] [4276] [INFO] Booting worker with pid: 4276
[2022-11-02 13:35:04 +0300] [4277] [INFO] Booting worker with pid: 4277
[2022-11-02 10:35:26 +0000] [4275] [INFO] Worker exiting (pid: 4275)
[2022-11-02 13:35:26 +0300] [4273] [INFO] Handling signal: term
[2022-11-02 10:35:26 +0000] [4277] [INFO] Worker exiting (pid: 4277)
[2022-11-02 10:35:26 +0000] [4276] [INFO] Worker exiting (pid: 4276)
[2022-11-02 13:35:27 +0300] [4273] [INFO] Shutting down: Master
[2022-11-02 13:35:27 +0300] [4284] [INFO] Starting gunicorn 20.1.0
[2022-11-02 13:35:27 +0300] [4284] [INFO] Listening at: http://127.0.0.1:8001 (4284)
[2022-11-02 13:35:27 +0300] [4284] [INFO] Using worker: sync
[2022-11-02 13:35:27 +0300] [4296] [INFO] Booting worker with pid: 4296
[2022-11-02 13:35:27 +0300] [4297] [INFO] Booting worker with pid: 4297
[2022-11-02 13:35:27 +0300] [4298] [INFO] Booting worker with pid: 4298
[2022-11-02 14:06:52 +0300] [4284] [INFO] Handling signal: term
[2022-11-02 11:06:52 +0000] [4296] [INFO] Worker exiting (pid: 4296)
[2022-11-02 11:06:52 +0000] [4298] [INFO] Worker exiting (pid: 4298)
[2022-11-02 11:06:52 +0000] [4297] [INFO] Worker exiting (pid: 4297)
[2022-11-02 14:06:52 +0300] [4284] [INFO] Shutting down: Master
[2022-11-02 14:06:52 +0300] [5503] [INFO] Starting gunicorn 20.1.0
[2022-11-02 14:06:52 +0300] [5503] [INFO] Listening at: http://127.0.0.1:8001 (5503)
[2022-11-02 14:06:52 +0300] [5503] [INFO] Using worker: sync
[2022-11-02 14:06:52 +0300] [5519] [INFO] Booting worker with pid: 5519
[2022-11-02 14:06:52 +0300] [5520] [INFO] Booting worker with pid: 5520
[2022-11-02 14:06:52 +0300] [5521] [INFO] Booting worker with pid: 5521
[2022-11-02 14:06:53 +0300] [5519] [ERROR] Exception in worker process
Traceback (most recent call last):
  File "/home/admsys/djangotest/venv/lib/python3.8/site-packages/gunicorn/arbiter.py", line 589, in spawn_worker
    worker.init_process()
  File "/home/admsys/djangotest/venv/lib/python3.8/site-packages/gunicorn/workers/base.py", line 134, in init_process
    self.load_wsgi()
  File "/home/admsys/djangotest/venv/lib/python3.8/site-packages/gunicorn/workers/base.py", line 146, in load_wsgi
    self.wsgi = self.app.wsgi()
  File "/home/admsys/djangotest/venv/lib/python3.8/site-packages/gunicorn/app/base.py", line 67, in wsgi
    self.callable = self.load()
  File "/home/admsys/djangotest/venv/lib/python3.8/site-packages/gunicorn/app/wsgiapp.py", line 58, in load
    return self.load_wsgiapp()
  File "/home/admsys/djangotest/venv/lib/python3.8/site-packages/gunicorn/app/wsgiapp.py", line 48, in load_wsgiapp
    return util.import_app(self.app_uri)
  File "/home/admsys/djangotest/venv/lib/python3.8/site-packages/gunicorn/util.py", line 359, in import_app
    mod = importlib.import_module(module)
  File "/usr/local/lib/python3.8/importlib/__init__.py", line 127, in import_module
    return _bootstrap._gcd_import(name[level:], package, level)
  File "<frozen importlib._bootstrap>", line 1014, in _gcd_import
  File "<frozen importlib._bootstrap>", line 991, in _find_and_load
  File "<frozen importlib._bootstrap>", line 975, in _find_and_load_unlocked
  File "<frozen importlib._bootstrap>", line 671, in _load_unlocked
  File "<frozen importlib._bootstrap_external>", line 848, in exec_module
  File "<frozen importlib._bootstrap>", line 219, in _call_with_frames_removed
  File "/home/admsys/djangotest/src/config/wsgi.py", line 16, in <module>
    application = get_wsgi_application()
  File "/home/admsys/djangotest/venv/lib/python3.8/site-packages/django/core/wsgi.py", line 12, in get_wsgi_application
    django.setup(set_prefix=False)
  File "/home/admsys/djangotest/venv/lib/python3.8/site-packages/django/__init__.py", line 19, in setup
    configure_logging(settings.LOGGING_CONFIG, settings.LOGGING)
  File "/home/admsys/djangotest/venv/lib/python3.8/site-packages/django/conf/__init__.py", line 92, in __getattr__
    self._setup(name)
  File "/home/admsys/djangotest/venv/lib/python3.8/site-packages/django/conf/__init__.py", line 79, in _setup
    self._wrapped = Settings(settings_module)
  File "/home/admsys/djangotest/venv/lib/python3.8/site-packages/django/conf/__init__.py", line 190, in __init__
    mod = importlib.import_module(self.SETTINGS_MODULE)
  File "/usr/local/lib/python3.8/importlib/__init__.py", line 127, in import_module
    return _bootstrap._gcd_import(name[level:], package, level)
  File "<frozen importlib._bootstrap>", line 1014, in _gcd_import
  File "<frozen importlib._bootstrap>", line 991, in _find_and_load
  File "<frozen importlib._bootstrap>", line 975, in _find_and_load_unlocked
  File "<frozen importlib._bootstrap>", line 671, in _load_unlocked
  File "<frozen importlib._bootstrap_external>", line 848, in exec_module
  File "<frozen importlib._bootstrap>", line 219, in _call_with_frames_removed
  File "/home/admsys/djangotest/src/config/settings.py", line 26, in <module>
    DEBUG = Fasle
NameError: name 'Fasle' is not defined
[2022-11-02 14:06:53 +0300] [5519] [INFO] Worker exiting (pid: 5519)
[2022-11-02 14:06:53 +0300] [5520] [ERROR] Exception in worker process
Traceback (most recent call last):
  File "/home/admsys/djangotest/venv/lib/python3.8/site-packages/gunicorn/arbiter.py", line 589, in spawn_worker
    worker.init_process()
  File "/home/admsys/djangotest/venv/lib/python3.8/site-packages/gunicorn/workers/base.py", line 134, in init_process
    self.load_wsgi()
  File "/home/admsys/djangotest/venv/lib/python3.8/site-packages/gunicorn/workers/base.py", line 146, in load_wsgi
    self.wsgi = self.app.wsgi()
  File "/home/admsys/djangotest/venv/lib/python3.8/site-packages/gunicorn/app/base.py", line 67, in wsgi
    self.callable = self.load()
  File "/home/admsys/djangotest/venv/lib/python3.8/site-packages/gunicorn/app/wsgiapp.py", line 58, in load
    return self.load_wsgiapp()
  File "/home/admsys/djangotest/venv/lib/python3.8/site-packages/gunicorn/app/wsgiapp.py", line 48, in load_wsgiapp
    return util.import_app(self.app_uri)
  File "/home/admsys/djangotest/venv/lib/python3.8/site-packages/gunicorn/util.py", line 359, in import_app
    mod = importlib.import_module(module)
  File "/usr/local/lib/python3.8/importlib/__init__.py", line 127, in import_module
    return _bootstrap._gcd_import(name[level:], package, level)
  File "<frozen importlib._bootstrap>", line 1014, in _gcd_import
  File "<frozen importlib._bootstrap>", line 991, in _find_and_load
  File "<frozen importlib._bootstrap>", line 975, in _find_and_load_unlocked
  File "<frozen importlib._bootstrap>", line 671, in _load_unlocked
  File "<frozen importlib._bootstrap_external>", line 848, in exec_module
  File "<frozen importlib._bootstrap>", line 219, in _call_with_frames_removed
  File "/home/admsys/djangotest/src/config/wsgi.py", line 16, in <module>
    application = get_wsgi_application()
  File "/home/admsys/djangotest/venv/lib/python3.8/site-packages/django/core/wsgi.py", line 12, in get_wsgi_application
    django.setup(set_prefix=False)
  File "/home/admsys/djangotest/venv/lib/python3.8/site-packages/django/__init__.py", line 19, in setup
    configure_logging(settings.LOGGING_CONFIG, settings.LOGGING)
  File "/home/admsys/djangotest/venv/lib/python3.8/site-packages/django/conf/__init__.py", line 92, in __getattr__
    self._setup(name)
  File "/home/admsys/djangotest/venv/lib/python3.8/site-packages/django/conf/__init__.py", line 79, in _setup
    self._wrapped = Settings(settings_module)
  File "/home/admsys/djangotest/venv/lib/python3.8/site-packages/django/conf/__init__.py", line 190, in __init__
    mod = importlib.import_module(self.SETTINGS_MODULE)
  File "/usr/local/lib/python3.8/importlib/__init__.py", line 127, in import_module
    return _bootstrap._gcd_import(name[level:], package, level)
  File "<frozen importlib._bootstrap>", line 1014, in _gcd_import
  File "<frozen importlib._bootstrap>", line 991, in _find_and_load
  File "<frozen importlib._bootstrap>", line 975, in _find_and_load_unlocked
  File "<frozen importlib._bootstrap>", line 671, in _load_unlocked
  File "<frozen importlib._bootstrap_external>", line 848, in exec_module
  File "<frozen importlib._bootstrap>", line 219, in _call_with_frames_removed
  File "/home/admsys/djangotest/src/config/settings.py", line 26, in <module>
    DEBUG = Fasle
NameError: name 'Fasle' is not defined
[2022-11-02 14:06:53 +0300] [5520] [INFO] Worker exiting (pid: 5520)
[2022-11-02 14:06:53 +0300] [5521] [ERROR] Exception in worker process
Traceback (most recent call last):
  File "/home/admsys/djangotest/venv/lib/python3.8/site-packages/gunicorn/arbiter.py", line 589, in spawn_worker
    worker.init_process()
  File "/home/admsys/djangotest/venv/lib/python3.8/site-packages/gunicorn/workers/base.py", line 134, in init_process
    self.load_wsgi()
  File "/home/admsys/djangotest/venv/lib/python3.8/site-packages/gunicorn/workers/base.py", line 146, in load_wsgi
    self.wsgi = self.app.wsgi()
  File "/home/admsys/djangotest/venv/lib/python3.8/site-packages/gunicorn/app/base.py", line 67, in wsgi
    self.callable = self.load()
  File "/home/admsys/djangotest/venv/lib/python3.8/site-packages/gunicorn/app/wsgiapp.py", line 58, in load
    return self.load_wsgiapp()
  File "/home/admsys/djangotest/venv/lib/python3.8/site-packages/gunicorn/app/wsgiapp.py", line 48, in load_wsgiapp
    return util.import_app(self.app_uri)
  File "/home/admsys/djangotest/venv/lib/python3.8/site-packages/gunicorn/util.py", line 359, in import_app
    mod = importlib.import_module(module)
  File "/usr/local/lib/python3.8/importlib/__init__.py", line 127, in import_module
    return _bootstrap._gcd_import(name[level:], package, level)
  File "<frozen importlib._bootstrap>", line 1014, in _gcd_import
  File "<frozen importlib._bootstrap>", line 991, in _find_and_load
  File "<frozen importlib._bootstrap>", line 975, in _find_and_load_unlocked
  File "<frozen importlib._bootstrap>", line 671, in _load_unlocked
  File "<frozen importlib._bootstrap_external>", line 848, in exec_module
  File "<frozen importlib._bootstrap>", line 219, in _call_with_frames_removed
  File "/home/admsys/djangotest/src/config/wsgi.py", line 16, in <module>
    application = get_wsgi_application()
  File "/home/admsys/djangotest/venv/lib/python3.8/site-packages/django/core/wsgi.py", line 12, in get_wsgi_application
    django.setup(set_prefix=False)
  File "/home/admsys/djangotest/venv/lib/python3.8/site-packages/django/__init__.py", line 19, in setup
    configure_logging(settings.LOGGING_CONFIG, settings.LOGGING)
  File "/home/admsys/djangotest/venv/lib/python3.8/site-packages/django/conf/__init__.py", line 92, in __getattr__
    self._setup(name)
  File "/home/admsys/djangotest/venv/lib/python3.8/site-packages/django/conf/__init__.py", line 79, in _setup
    self._wrapped = Settings(settings_module)
  File "/home/admsys/djangotest/venv/lib/python3.8/site-packages/django/conf/__init__.py", line 190, in __init__
    mod = importlib.import_module(self.SETTINGS_MODULE)
  File "/usr/local/lib/python3.8/importlib/__init__.py", line 127, in import_module
    return _bootstrap._gcd_import(name[level:], package, level)
  File "<frozen importlib._bootstrap>", line 1014, in _gcd_import
  File "<frozen importlib._bootstrap>", line 991, in _find_and_load
  File "<frozen importlib._bootstrap>", line 975, in _find_and_load_unlocked
  File "<frozen importlib._bootstrap>", line 671, in _load_unlocked
  File "<frozen importlib._bootstrap_external>", line 848, in exec_module
  File "<frozen importlib._bootstrap>", line 219, in _call_with_frames_removed
  File "/home/admsys/djangotest/src/config/settings.py", line 26, in <module>
    DEBUG = Fasle
NameError: name 'Fasle' is not defined
[2022-11-02 14:06:53 +0300] [5521] [INFO] Worker exiting (pid: 5521)
[2022-11-02 14:06:53 +0300] [5524] [INFO] Starting gunicorn 20.1.0
[2022-11-02 14:06:53 +0300] [5524] [INFO] Listening at: http://127.0.0.1:8001 (5524)
[2022-11-02 14:06:53 +0300] [5524] [INFO] Using worker: sync
[2022-11-02 14:06:53 +0300] [5526] [INFO] Booting worker with pid: 5526
[2022-11-02 14:06:53 +0300] [5527] [INFO] Booting worker with pid: 5527
[2022-11-02 14:06:54 +0300] [5528] [INFO] Booting worker with pid: 5528
[2022-11-02 14:06:54 +0300] [5526] [ERROR] Exception in worker process
Traceback (most recent call last):
  File "/home/admsys/djangotest/venv/lib/python3.8/site-packages/gunicorn/arbiter.py", line 589, in spawn_worker
    worker.init_process()
  File "/home/admsys/djangotest/venv/lib/python3.8/site-packages/gunicorn/workers/base.py", line 134, in init_process
    self.load_wsgi()
  File "/home/admsys/djangotest/venv/lib/python3.8/site-packages/gunicorn/workers/base.py", line 146, in load_wsgi
    self.wsgi = self.app.wsgi()
  File "/home/admsys/djangotest/venv/lib/python3.8/site-packages/gunicorn/app/base.py", line 67, in wsgi
    self.callable = self.load()
  File "/home/admsys/djangotest/venv/lib/python3.8/site-packages/gunicorn/app/wsgiapp.py", line 58, in load
    return self.load_wsgiapp()
  File "/home/admsys/djangotest/venv/lib/python3.8/site-packages/gunicorn/app/wsgiapp.py", line 48, in load_wsgiapp
    return util.import_app(self.app_uri)
  File "/home/admsys/djangotest/venv/lib/python3.8/site-packages/gunicorn/util.py", line 359, in import_app
    mod = importlib.import_module(module)
  File "/usr/local/lib/python3.8/importlib/__init__.py", line 127, in import_module
    return _bootstrap._gcd_import(name[level:], package, level)
  File "<frozen importlib._bootstrap>", line 1014, in _gcd_import
  File "<frozen importlib._bootstrap>", line 991, in _find_and_load
  File "<frozen importlib._bootstrap>", line 975, in _find_and_load_unlocked
  File "<frozen importlib._bootstrap>", line 671, in _load_unlocked
  File "<frozen importlib._bootstrap_external>", line 848, in exec_module
  File "<frozen importlib._bootstrap>", line 219, in _call_with_frames_removed
  File "/home/admsys/djangotest/src/config/wsgi.py", line 16, in <module>
    application = get_wsgi_application()
  File "/home/admsys/djangotest/venv/lib/python3.8/site-packages/django/core/wsgi.py", line 12, in get_wsgi_application
    django.setup(set_prefix=False)
  File "/home/admsys/djangotest/venv/lib/python3.8/site-packages/django/__init__.py", line 19, in setup
    configure_logging(settings.LOGGING_CONFIG, settings.LOGGING)
  File "/home/admsys/djangotest/venv/lib/python3.8/site-packages/django/conf/__init__.py", line 92, in __getattr__
    self._setup(name)
  File "/home/admsys/djangotest/venv/lib/python3.8/site-packages/django/conf/__init__.py", line 79, in _setup
    self._wrapped = Settings(settings_module)
  File "/home/admsys/djangotest/venv/lib/python3.8/site-packages/django/conf/__init__.py", line 190, in __init__
    mod = importlib.import_module(self.SETTINGS_MODULE)
  File "/usr/local/lib/python3.8/importlib/__init__.py", line 127, in import_module
    return _bootstrap._gcd_import(name[level:], package, level)
  File "<frozen importlib._bootstrap>", line 1014, in _gcd_import
  File "<frozen importlib._bootstrap>", line 991, in _find_and_load
  File "<frozen importlib._bootstrap>", line 975, in _find_and_load_unlocked
  File "<frozen importlib._bootstrap>", line 671, in _load_unlocked
  File "<frozen importlib._bootstrap_external>", line 848, in exec_module
  File "<frozen importlib._bootstrap>", line 219, in _call_with_frames_removed
  File "/home/admsys/djangotest/src/config/settings.py", line 26, in <module>
    DEBUG = Fasle
NameError: name 'Fasle' is not defined
[2022-11-02 14:06:54 +0300] [5526] [INFO] Worker exiting (pid: 5526)
[2022-11-02 14:06:54 +0300] [5527] [ERROR] Exception in worker process
Traceback (most recent call last):
  File "/home/admsys/djangotest/venv/lib/python3.8/site-packages/gunicorn/arbiter.py", line 589, in spawn_worker
    worker.init_process()
  File "/home/admsys/djangotest/venv/lib/python3.8/site-packages/gunicorn/workers/base.py", line 134, in init_process
    self.load_wsgi()
  File "/home/admsys/djangotest/venv/lib/python3.8/site-packages/gunicorn/workers/base.py", line 146, in load_wsgi
    self.wsgi = self.app.wsgi()
  File "/home/admsys/djangotest/venv/lib/python3.8/site-packages/gunicorn/app/base.py", line 67, in wsgi
    self.callable = self.load()
  File "/home/admsys/djangotest/venv/lib/python3.8/site-packages/gunicorn/app/wsgiapp.py", line 58, in load
    return self.load_wsgiapp()
  File "/home/admsys/djangotest/venv/lib/python3.8/site-packages/gunicorn/app/wsgiapp.py", line 48, in load_wsgiapp
    return util.import_app(self.app_uri)
  File "/home/admsys/djangotest/venv/lib/python3.8/site-packages/gunicorn/util.py", line 359, in import_app
    mod = importlib.import_module(module)
  File "/usr/local/lib/python3.8/importlib/__init__.py", line 127, in import_module
    return _bootstrap._gcd_import(name[level:], package, level)
  File "<frozen importlib._bootstrap>", line 1014, in _gcd_import
  File "<frozen importlib._bootstrap>", line 991, in _find_and_load
  File "<frozen importlib._bootstrap>", line 975, in _find_and_load_unlocked
  File "<frozen importlib._bootstrap>", line 671, in _load_unlocked
  File "<frozen importlib._bootstrap_external>", line 848, in exec_module
  File "<frozen importlib._bootstrap>", line 219, in _call_with_frames_removed
  File "/home/admsys/djangotest/src/config/wsgi.py", line 16, in <module>
    application = get_wsgi_application()
  File "/home/admsys/djangotest/venv/lib/python3.8/site-packages/django/core/wsgi.py", line 12, in get_wsgi_application
    django.setup(set_prefix=False)
  File "/home/admsys/djangotest/venv/lib/python3.8/site-packages/django/__init__.py", line 19, in setup
    configure_logging(settings.LOGGING_CONFIG, settings.LOGGING)
  File "/home/admsys/djangotest/venv/lib/python3.8/site-packages/django/conf/__init__.py", line 92, in __getattr__
    self._setup(name)
  File "/home/admsys/djangotest/venv/lib/python3.8/site-packages/django/conf/__init__.py", line 79, in _setup
    self._wrapped = Settings(settings_module)
  File "/home/admsys/djangotest/venv/lib/python3.8/site-packages/django/conf/__init__.py", line 190, in __init__
    mod = importlib.import_module(self.SETTINGS_MODULE)
  File "/usr/local/lib/python3.8/importlib/__init__.py", line 127, in import_module
    return _bootstrap._gcd_import(name[level:], package, level)
  File "<frozen importlib._bootstrap>", line 1014, in _gcd_import
  File "<frozen importlib._bootstrap>", line 991, in _find_and_load
  File "<frozen importlib._bootstrap>", line 975, in _find_and_load_unlocked
  File "<frozen importlib._bootstrap>", line 671, in _load_unlocked
  File "<frozen importlib._bootstrap_external>", line 848, in exec_module
  File "<frozen importlib._bootstrap>", line 219, in _call_with_frames_removed
  File "/home/admsys/djangotest/src/config/settings.py", line 26, in <module>
    DEBUG = Fasle
NameError: name 'Fasle' is not defined
[2022-11-02 14:06:54 +0300] [5527] [INFO] Worker exiting (pid: 5527)
[2022-11-02 14:06:54 +0300] [5524] [WARNING] Worker with pid 5527 was terminated due to signal 15
[2022-11-02 14:06:54 +0300] [5528] [ERROR] Exception in worker process
Traceback (most recent call last):
  File "/home/admsys/djangotest/venv/lib/python3.8/site-packages/gunicorn/arbiter.py", line 589, in spawn_worker
    worker.init_process()
  File "/home/admsys/djangotest/venv/lib/python3.8/site-packages/gunicorn/workers/base.py", line 134, in init_process
    self.load_wsgi()
  File "/home/admsys/djangotest/venv/lib/python3.8/site-packages/gunicorn/workers/base.py", line 146, in load_wsgi
    self.wsgi = self.app.wsgi()
  File "/home/admsys/djangotest/venv/lib/python3.8/site-packages/gunicorn/app/base.py", line 67, in wsgi
    self.callable = self.load()
  File "/home/admsys/djangotest/venv/lib/python3.8/site-packages/gunicorn/app/wsgiapp.py", line 58, in load
    return self.load_wsgiapp()
  File "/home/admsys/djangotest/venv/lib/python3.8/site-packages/gunicorn/app/wsgiapp.py", line 48, in load_wsgiapp
    return util.import_app(self.app_uri)
  File "/home/admsys/djangotest/venv/lib/python3.8/site-packages/gunicorn/util.py", line 359, in import_app
    mod = importlib.import_module(module)
  File "/usr/local/lib/python3.8/importlib/__init__.py", line 127, in import_module
    return _bootstrap._gcd_import(name[level:], package, level)
  File "<frozen importlib._bootstrap>", line 1014, in _gcd_import
  File "<frozen importlib._bootstrap>", line 991, in _find_and_load
  File "<frozen importlib._bootstrap>", line 975, in _find_and_load_unlocked
  File "<frozen importlib._bootstrap>", line 671, in _load_unlocked
  File "<frozen importlib._bootstrap_external>", line 848, in exec_module
  File "<frozen importlib._bootstrap>", line 219, in _call_with_frames_removed
  File "/home/admsys/djangotest/src/config/wsgi.py", line 16, in <module>
    application = get_wsgi_application()
  File "/home/admsys/djangotest/venv/lib/python3.8/site-packages/django/core/wsgi.py", line 12, in get_wsgi_application
    django.setup(set_prefix=False)
  File "/home/admsys/djangotest/venv/lib/python3.8/site-packages/django/__init__.py", line 19, in setup
    configure_logging(settings.LOGGING_CONFIG, settings.LOGGING)
  File "/home/admsys/djangotest/venv/lib/python3.8/site-packages/django/conf/__init__.py", line 92, in __getattr__
    self._setup(name)
  File "/home/admsys/djangotest/venv/lib/python3.8/site-packages/django/conf/__init__.py", line 79, in _setup
    self._wrapped = Settings(settings_module)
  File "/home/admsys/djangotest/venv/lib/python3.8/site-packages/django/conf/__init__.py", line 190, in __init__
    mod = importlib.import_module(self.SETTINGS_MODULE)
  File "/usr/local/lib/python3.8/importlib/__init__.py", line 127, in import_module
    return _bootstrap._gcd_import(name[level:], package, level)
  File "<frozen importlib._bootstrap>", line 1014, in _gcd_import
  File "<frozen importlib._bootstrap>", line 991, in _find_and_load
  File "<frozen importlib._bootstrap>", line 975, in _find_and_load_unlocked
  File "<frozen importlib._bootstrap>", line 671, in _load_unlocked
  File "<frozen importlib._bootstrap_external>", line 848, in exec_module
  File "<frozen importlib._bootstrap>", line 219, in _call_with_frames_removed
  File "/home/admsys/djangotest/src/config/settings.py", line 26, in <module>
    DEBUG = Fasle
NameError: name 'Fasle' is not defined
[2022-11-02 14:06:54 +0300] [5528] [INFO] Worker exiting (pid: 5528)
[2022-11-02 14:06:55 +0300] [5530] [INFO] Starting gunicorn 20.1.0
[2022-11-02 14:06:55 +0300] [5530] [INFO] Listening at: http://127.0.0.1:8001 (5530)
[2022-11-02 14:06:55 +0300] [5530] [INFO] Using worker: sync
[2022-11-02 14:06:55 +0300] [5532] [INFO] Booting worker with pid: 5532
[2022-11-02 14:06:55 +0300] [5533] [INFO] Booting worker with pid: 5533
[2022-11-02 14:06:55 +0300] [5534] [INFO] Booting worker with pid: 5534
[2022-11-02 14:06:55 +0300] [5532] [ERROR] Exception in worker process
Traceback (most recent call last):
  File "/home/admsys/djangotest/venv/lib/python3.8/site-packages/gunicorn/arbiter.py", line 589, in spawn_worker
    worker.init_process()
  File "/home/admsys/djangotest/venv/lib/python3.8/site-packages/gunicorn/workers/base.py", line 134, in init_process
    self.load_wsgi()
  File "/home/admsys/djangotest/venv/lib/python3.8/site-packages/gunicorn/workers/base.py", line 146, in load_wsgi
    self.wsgi = self.app.wsgi()
  File "/home/admsys/djangotest/venv/lib/python3.8/site-packages/gunicorn/app/base.py", line 67, in wsgi
    self.callable = self.load()
  File "/home/admsys/djangotest/venv/lib/python3.8/site-packages/gunicorn/app/wsgiapp.py", line 58, in load
    return self.load_wsgiapp()
  File "/home/admsys/djangotest/venv/lib/python3.8/site-packages/gunicorn/app/wsgiapp.py", line 48, in load_wsgiapp
    return util.import_app(self.app_uri)
  File "/home/admsys/djangotest/venv/lib/python3.8/site-packages/gunicorn/util.py", line 359, in import_app
    mod = importlib.import_module(module)
  File "/usr/local/lib/python3.8/importlib/__init__.py", line 127, in import_module
    return _bootstrap._gcd_import(name[level:], package, level)
  File "<frozen importlib._bootstrap>", line 1014, in _gcd_import
  File "<frozen importlib._bootstrap>", line 991, in _find_and_load
  File "<frozen importlib._bootstrap>", line 975, in _find_and_load_unlocked
  File "<frozen importlib._bootstrap>", line 671, in _load_unlocked
  File "<frozen importlib._bootstrap_external>", line 848, in exec_module
  File "<frozen importlib._bootstrap>", line 219, in _call_with_frames_removed
  File "/home/admsys/djangotest/src/config/wsgi.py", line 16, in <module>
    application = get_wsgi_application()
  File "/home/admsys/djangotest/venv/lib/python3.8/site-packages/django/core/wsgi.py", line 12, in get_wsgi_application
    django.setup(set_prefix=False)
  File "/home/admsys/djangotest/venv/lib/python3.8/site-packages/django/__init__.py", line 19, in setup
    configure_logging(settings.LOGGING_CONFIG, settings.LOGGING)
  File "/home/admsys/djangotest/venv/lib/python3.8/site-packages/django/conf/__init__.py", line 92, in __getattr__
    self._setup(name)
  File "/home/admsys/djangotest/venv/lib/python3.8/site-packages/django/conf/__init__.py", line 79, in _setup
    self._wrapped = Settings(settings_module)
  File "/home/admsys/djangotest/venv/lib/python3.8/site-packages/django/conf/__init__.py", line 190, in __init__
    mod = importlib.import_module(self.SETTINGS_MODULE)
  File "/usr/local/lib/python3.8/importlib/__init__.py", line 127, in import_module
    return _bootstrap._gcd_import(name[level:], package, level)
  File "<frozen importlib._bootstrap>", line 1014, in _gcd_import
  File "<frozen importlib._bootstrap>", line 991, in _find_and_load
  File "<frozen importlib._bootstrap>", line 975, in _find_and_load_unlocked
  File "<frozen importlib._bootstrap>", line 671, in _load_unlocked
  File "<frozen importlib._bootstrap_external>", line 848, in exec_module
  File "<frozen importlib._bootstrap>", line 219, in _call_with_frames_removed
  File "/home/admsys/djangotest/src/config/settings.py", line 26, in <module>
    DEBUG = Fasle
NameError: name 'Fasle' is not defined
[2022-11-02 14:06:55 +0300] [5532] [INFO] Worker exiting (pid: 5532)
[2022-11-02 14:06:55 +0300] [5533] [ERROR] Exception in worker process
Traceback (most recent call last):
  File "/home/admsys/djangotest/venv/lib/python3.8/site-packages/gunicorn/arbiter.py", line 589, in spawn_worker
    worker.init_process()
  File "/home/admsys/djangotest/venv/lib/python3.8/site-packages/gunicorn/workers/base.py", line 134, in init_process
    self.load_wsgi()
  File "/home/admsys/djangotest/venv/lib/python3.8/site-packages/gunicorn/workers/base.py", line 146, in load_wsgi
    self.wsgi = self.app.wsgi()
  File "/home/admsys/djangotest/venv/lib/python3.8/site-packages/gunicorn/app/base.py", line 67, in wsgi
    self.callable = self.load()
  File "/home/admsys/djangotest/venv/lib/python3.8/site-packages/gunicorn/app/wsgiapp.py", line 58, in load
    return self.load_wsgiapp()
  File "/home/admsys/djangotest/venv/lib/python3.8/site-packages/gunicorn/app/wsgiapp.py", line 48, in load_wsgiapp
    return util.import_app(self.app_uri)
  File "/home/admsys/djangotest/venv/lib/python3.8/site-packages/gunicorn/util.py", line 359, in import_app
    mod = importlib.import_module(module)
  File "/usr/local/lib/python3.8/importlib/__init__.py", line 127, in import_module
    return _bootstrap._gcd_import(name[level:], package, level)
  File "<frozen importlib._bootstrap>", line 1014, in _gcd_import
  File "<frozen importlib._bootstrap>", line 991, in _find_and_load
  File "<frozen importlib._bootstrap>", line 975, in _find_and_load_unlocked
  File "<frozen importlib._bootstrap>", line 671, in _load_unlocked
  File "<frozen importlib._bootstrap_external>", line 848, in exec_module
  File "<frozen importlib._bootstrap>", line 219, in _call_with_frames_removed
  File "/home/admsys/djangotest/src/config/wsgi.py", line 16, in <module>
    application = get_wsgi_application()
  File "/home/admsys/djangotest/venv/lib/python3.8/site-packages/django/core/wsgi.py", line 12, in get_wsgi_application
    django.setup(set_prefix=False)
  File "/home/admsys/djangotest/venv/lib/python3.8/site-packages/django/__init__.py", line 19, in setup
    configure_logging(settings.LOGGING_CONFIG, settings.LOGGING)
  File "/home/admsys/djangotest/venv/lib/python3.8/site-packages/django/conf/__init__.py", line 92, in __getattr__
    self._setup(name)
  File "/home/admsys/djangotest/venv/lib/python3.8/site-packages/django/conf/__init__.py", line 79, in _setup
    self._wrapped = Settings(settings_module)
  File "/home/admsys/djangotest/venv/lib/python3.8/site-packages/django/conf/__init__.py", line 190, in __init__
    mod = importlib.import_module(self.SETTINGS_MODULE)
  File "/usr/local/lib/python3.8/importlib/__init__.py", line 127, in import_module
    return _bootstrap._gcd_import(name[level:], package, level)
  File "<frozen importlib._bootstrap>", line 1014, in _gcd_import
  File "<frozen importlib._bootstrap>", line 991, in _find_and_load
  File "<frozen importlib._bootstrap>", line 975, in _find_and_load_unlocked
  File "<frozen importlib._bootstrap>", line 671, in _load_unlocked
  File "<frozen importlib._bootstrap_external>", line 848, in exec_module
  File "<frozen importlib._bootstrap>", line 219, in _call_with_frames_removed
  File "/home/admsys/djangotest/src/config/settings.py", line 26, in <module>
    DEBUG = Fasle
NameError: name 'Fasle' is not defined
[2022-11-02 14:06:55 +0300] [5533] [INFO] Worker exiting (pid: 5533)
[2022-11-02 14:06:55 +0300] [5530] [WARNING] Worker with pid 5533 was terminated due to signal 15
[2022-11-02 14:06:55 +0300] [5534] [ERROR] Exception in worker process
Traceback (most recent call last):
  File "/home/admsys/djangotest/venv/lib/python3.8/site-packages/gunicorn/arbiter.py", line 589, in spawn_worker
    worker.init_process()
  File "/home/admsys/djangotest/venv/lib/python3.8/site-packages/gunicorn/workers/base.py", line 134, in init_process
    self.load_wsgi()
  File "/home/admsys/djangotest/venv/lib/python3.8/site-packages/gunicorn/workers/base.py", line 146, in load_wsgi
    self.wsgi = self.app.wsgi()
  File "/home/admsys/djangotest/venv/lib/python3.8/site-packages/gunicorn/app/base.py", line 67, in wsgi
    self.callable = self.load()
  File "/home/admsys/djangotest/venv/lib/python3.8/site-packages/gunicorn/app/wsgiapp.py", line 58, in load
    return self.load_wsgiapp()
  File "/home/admsys/djangotest/venv/lib/python3.8/site-packages/gunicorn/app/wsgiapp.py", line 48, in load_wsgiapp
    return util.import_app(self.app_uri)
  File "/home/admsys/djangotest/venv/lib/python3.8/site-packages/gunicorn/util.py", line 359, in import_app
    mod = importlib.import_module(module)
  File "/usr/local/lib/python3.8/importlib/__init__.py", line 127, in import_module
    return _bootstrap._gcd_import(name[level:], package, level)
  File "<frozen importlib._bootstrap>", line 1014, in _gcd_import
  File "<frozen importlib._bootstrap>", line 991, in _find_and_load
  File "<frozen importlib._bootstrap>", line 975, in _find_and_load_unlocked
  File "<frozen importlib._bootstrap>", line 671, in _load_unlocked
  File "<frozen importlib._bootstrap_external>", line 848, in exec_module
  File "<frozen importlib._bootstrap>", line 219, in _call_with_frames_removed
  File "/home/admsys/djangotest/src/config/wsgi.py", line 16, in <module>
    application = get_wsgi_application()
  File "/home/admsys/djangotest/venv/lib/python3.8/site-packages/django/core/wsgi.py", line 12, in get_wsgi_application
    django.setup(set_prefix=False)
  File "/home/admsys/djangotest/venv/lib/python3.8/site-packages/django/__init__.py", line 19, in setup
    configure_logging(settings.LOGGING_CONFIG, settings.LOGGING)
  File "/home/admsys/djangotest/venv/lib/python3.8/site-packages/django/conf/__init__.py", line 92, in __getattr__
    self._setup(name)
  File "/home/admsys/djangotest/venv/lib/python3.8/site-packages/django/conf/__init__.py", line 79, in _setup
    self._wrapped = Settings(settings_module)
  File "/home/admsys/djangotest/venv/lib/python3.8/site-packages/django/conf/__init__.py", line 190, in __init__
    mod = importlib.import_module(self.SETTINGS_MODULE)
  File "/usr/local/lib/python3.8/importlib/__init__.py", line 127, in import_module
    return _bootstrap._gcd_import(name[level:], package, level)
  File "<frozen importlib._bootstrap>", line 1014, in _gcd_import
  File "<frozen importlib._bootstrap>", line 991, in _find_and_load
  File "<frozen importlib._bootstrap>", line 975, in _find_and_load_unlocked
  File "<frozen importlib._bootstrap>", line 671, in _load_unlocked
  File "<frozen importlib._bootstrap_external>", line 848, in exec_module
  File "<frozen importlib._bootstrap>", line 219, in _call_with_frames_removed
  File "/home/admsys/djangotest/src/config/settings.py", line 26, in <module>
    DEBUG = Fasle
NameError: name 'Fasle' is not defined
[2022-11-02 14:06:55 +0300] [5534] [INFO] Worker exiting (pid: 5534)
[2022-11-02 14:06:56 +0300] [5535] [INFO] Starting gunicorn 20.1.0
[2022-11-02 14:06:56 +0300] [5535] [INFO] Listening at: http://127.0.0.1:8001 (5535)
[2022-11-02 14:06:56 +0300] [5535] [INFO] Using worker: sync
[2022-11-02 14:06:56 +0300] [5540] [INFO] Booting worker with pid: 5540
[2022-11-02 14:06:56 +0300] [5541] [INFO] Booting worker with pid: 5541
[2022-11-02 14:06:56 +0300] [5542] [INFO] Booting worker with pid: 5542
[2022-11-02 14:06:56 +0300] [5540] [ERROR] Exception in worker process
Traceback (most recent call last):
  File "/home/admsys/djangotest/venv/lib/python3.8/site-packages/gunicorn/arbiter.py", line 589, in spawn_worker
    worker.init_process()
  File "/home/admsys/djangotest/venv/lib/python3.8/site-packages/gunicorn/workers/base.py", line 134, in init_process
    self.load_wsgi()
  File "/home/admsys/djangotest/venv/lib/python3.8/site-packages/gunicorn/workers/base.py", line 146, in load_wsgi
    self.wsgi = self.app.wsgi()
  File "/home/admsys/djangotest/venv/lib/python3.8/site-packages/gunicorn/app/base.py", line 67, in wsgi
    self.callable = self.load()
  File "/home/admsys/djangotest/venv/lib/python3.8/site-packages/gunicorn/app/wsgiapp.py", line 58, in load
    return self.load_wsgiapp()
  File "/home/admsys/djangotest/venv/lib/python3.8/site-packages/gunicorn/app/wsgiapp.py", line 48, in load_wsgiapp
    return util.import_app(self.app_uri)
  File "/home/admsys/djangotest/venv/lib/python3.8/site-packages/gunicorn/util.py", line 359, in import_app
    mod = importlib.import_module(module)
  File "/usr/local/lib/python3.8/importlib/__init__.py", line 127, in import_module
    return _bootstrap._gcd_import(name[level:], package, level)
  File "<frozen importlib._bootstrap>", line 1014, in _gcd_import
  File "<frozen importlib._bootstrap>", line 991, in _find_and_load
  File "<frozen importlib._bootstrap>", line 975, in _find_and_load_unlocked
  File "<frozen importlib._bootstrap>", line 671, in _load_unlocked
  File "<frozen importlib._bootstrap_external>", line 848, in exec_module
  File "<frozen importlib._bootstrap>", line 219, in _call_with_frames_removed
  File "/home/admsys/djangotest/src/config/wsgi.py", line 16, in <module>
    application = get_wsgi_application()
  File "/home/admsys/djangotest/venv/lib/python3.8/site-packages/django/core/wsgi.py", line 12, in get_wsgi_application
    django.setup(set_prefix=False)
  File "/home/admsys/djangotest/venv/lib/python3.8/site-packages/django/__init__.py", line 19, in setup
    configure_logging(settings.LOGGING_CONFIG, settings.LOGGING)
  File "/home/admsys/djangotest/venv/lib/python3.8/site-packages/django/conf/__init__.py", line 92, in __getattr__
    self._setup(name)
  File "/home/admsys/djangotest/venv/lib/python3.8/site-packages/django/conf/__init__.py", line 79, in _setup
    self._wrapped = Settings(settings_module)
  File "/home/admsys/djangotest/venv/lib/python3.8/site-packages/django/conf/__init__.py", line 190, in __init__
    mod = importlib.import_module(self.SETTINGS_MODULE)
  File "/usr/local/lib/python3.8/importlib/__init__.py", line 127, in import_module
    return _bootstrap._gcd_import(name[level:], package, level)
  File "<frozen importlib._bootstrap>", line 1014, in _gcd_import
  File "<frozen importlib._bootstrap>", line 991, in _find_and_load
  File "<frozen importlib._bootstrap>", line 975, in _find_and_load_unlocked
  File "<frozen importlib._bootstrap>", line 671, in _load_unlocked
  File "<frozen importlib._bootstrap_external>", line 848, in exec_module
  File "<frozen importlib._bootstrap>", line 219, in _call_with_frames_removed
  File "/home/admsys/djangotest/src/config/settings.py", line 26, in <module>
    DEBUG = Fasle
NameError: name 'Fasle' is not defined
[2022-11-02 14:06:56 +0300] [5540] [INFO] Worker exiting (pid: 5540)
[2022-11-02 14:06:56 +0300] [5542] [ERROR] Exception in worker process
Traceback (most recent call last):
  File "/home/admsys/djangotest/venv/lib/python3.8/site-packages/gunicorn/arbiter.py", line 589, in spawn_worker
    worker.init_process()
  File "/home/admsys/djangotest/venv/lib/python3.8/site-packages/gunicorn/workers/base.py", line 134, in init_process
    self.load_wsgi()
  File "/home/admsys/djangotest/venv/lib/python3.8/site-packages/gunicorn/workers/base.py", line 146, in load_wsgi
    self.wsgi = self.app.wsgi()
  File "/home/admsys/djangotest/venv/lib/python3.8/site-packages/gunicorn/app/base.py", line 67, in wsgi
    self.callable = self.load()
  File "/home/admsys/djangotest/venv/lib/python3.8/site-packages/gunicorn/app/wsgiapp.py", line 58, in load
    return self.load_wsgiapp()
  File "/home/admsys/djangotest/venv/lib/python3.8/site-packages/gunicorn/app/wsgiapp.py", line 48, in load_wsgiapp
    return util.import_app(self.app_uri)
  File "/home/admsys/djangotest/venv/lib/python3.8/site-packages/gunicorn/util.py", line 359, in import_app
    mod = importlib.import_module(module)
  File "/usr/local/lib/python3.8/importlib/__init__.py", line 127, in import_module
    return _bootstrap._gcd_import(name[level:], package, level)
  File "<frozen importlib._bootstrap>", line 1014, in _gcd_import
  File "<frozen importlib._bootstrap>", line 991, in _find_and_load
  File "<frozen importlib._bootstrap>", line 975, in _find_and_load_unlocked
  File "<frozen importlib._bootstrap>", line 671, in _load_unlocked
  File "<frozen importlib._bootstrap_external>", line 848, in exec_module
  File "<frozen importlib._bootstrap>", line 219, in _call_with_frames_removed
  File "/home/admsys/djangotest/src/config/wsgi.py", line 16, in <module>
    application = get_wsgi_application()
  File "/home/admsys/djangotest/venv/lib/python3.8/site-packages/django/core/wsgi.py", line 12, in get_wsgi_application
    django.setup(set_prefix=False)
  File "/home/admsys/djangotest/venv/lib/python3.8/site-packages/django/__init__.py", line 19, in setup
    configure_logging(settings.LOGGING_CONFIG, settings.LOGGING)
  File "/home/admsys/djangotest/venv/lib/python3.8/site-packages/django/conf/__init__.py", line 92, in __getattr__
    self._setup(name)
  File "/home/admsys/djangotest/venv/lib/python3.8/site-packages/django/conf/__init__.py", line 79, in _setup
    self._wrapped = Settings(settings_module)
  File "/home/admsys/djangotest/venv/lib/python3.8/site-packages/django/conf/__init__.py", line 190, in __init__
    mod = importlib.import_module(self.SETTINGS_MODULE)
  File "/usr/local/lib/python3.8/importlib/__init__.py", line 127, in import_module
    return _bootstrap._gcd_import(name[level:], package, level)
  File "<frozen importlib._bootstrap>", line 1014, in _gcd_import
  File "<frozen importlib._bootstrap>", line 991, in _find_and_load
  File "<frozen importlib._bootstrap>", line 975, in _find_and_load_unlocked
  File "<frozen importlib._bootstrap>", line 671, in _load_unlocked
  File "<frozen importlib._bootstrap_external>", line 848, in exec_module
  File "<frozen importlib._bootstrap>", line 219, in _call_with_frames_removed
  File "/home/admsys/djangotest/src/config/settings.py", line 26, in <module>
    DEBUG = Fasle
NameError: name 'Fasle' is not defined
[2022-11-02 14:06:56 +0300] [5542] [INFO] Worker exiting (pid: 5542)
[2022-11-02 14:06:56 +0300] [5541] [ERROR] Exception in worker process
Traceback (most recent call last):
  File "/home/admsys/djangotest/venv/lib/python3.8/site-packages/gunicorn/arbiter.py", line 589, in spawn_worker
    worker.init_process()
  File "/home/admsys/djangotest/venv/lib/python3.8/site-packages/gunicorn/workers/base.py", line 134, in init_process
    self.load_wsgi()
  File "/home/admsys/djangotest/venv/lib/python3.8/site-packages/gunicorn/workers/base.py", line 146, in load_wsgi
    self.wsgi = self.app.wsgi()
  File "/home/admsys/djangotest/venv/lib/python3.8/site-packages/gunicorn/app/base.py", line 67, in wsgi
    self.callable = self.load()
  File "/home/admsys/djangotest/venv/lib/python3.8/site-packages/gunicorn/app/wsgiapp.py", line 58, in load
    return self.load_wsgiapp()
  File "/home/admsys/djangotest/venv/lib/python3.8/site-packages/gunicorn/app/wsgiapp.py", line 48, in load_wsgiapp
    return util.import_app(self.app_uri)
  File "/home/admsys/djangotest/venv/lib/python3.8/site-packages/gunicorn/util.py", line 359, in import_app
    mod = importlib.import_module(module)
  File "/usr/local/lib/python3.8/importlib/__init__.py", line 127, in import_module
    return _bootstrap._gcd_import(name[level:], package, level)
  File "<frozen importlib._bootstrap>", line 1014, in _gcd_import
  File "<frozen importlib._bootstrap>", line 991, in _find_and_load
  File "<frozen importlib._bootstrap>", line 975, in _find_and_load_unlocked
  File "<frozen importlib._bootstrap>", line 671, in _load_unlocked
  File "<frozen importlib._bootstrap_external>", line 848, in exec_module
  File "<frozen importlib._bootstrap>", line 219, in _call_with_frames_removed
  File "/home/admsys/djangotest/src/config/wsgi.py", line 16, in <module>
    application = get_wsgi_application()
  File "/home/admsys/djangotest/venv/lib/python3.8/site-packages/django/core/wsgi.py", line 12, in get_wsgi_application
    django.setup(set_prefix=False)
  File "/home/admsys/djangotest/venv/lib/python3.8/site-packages/django/__init__.py", line 19, in setup
    configure_logging(settings.LOGGING_CONFIG, settings.LOGGING)
  File "/home/admsys/djangotest/venv/lib/python3.8/site-packages/django/conf/__init__.py", line 92, in __getattr__
    self._setup(name)
  File "/home/admsys/djangotest/venv/lib/python3.8/site-packages/django/conf/__init__.py", line 79, in _setup
    self._wrapped = Settings(settings_module)
  File "/home/admsys/djangotest/venv/lib/python3.8/site-packages/django/conf/__init__.py", line 190, in __init__
    mod = importlib.import_module(self.SETTINGS_MODULE)
  File "/usr/local/lib/python3.8/importlib/__init__.py", line 127, in import_module
    return _bootstrap._gcd_import(name[level:], package, level)
  File "<frozen importlib._bootstrap>", line 1014, in _gcd_import
  File "<frozen importlib._bootstrap>", line 991, in _find_and_load
  File "<frozen importlib._bootstrap>", line 975, in _find_and_load_unlocked
  File "<frozen importlib._bootstrap>", line 671, in _load_unlocked
  File "<frozen importlib._bootstrap_external>", line 848, in exec_module
  File "<frozen importlib._bootstrap>", line 219, in _call_with_frames_removed
  File "/home/admsys/djangotest/src/config/settings.py", line 26, in <module>
    DEBUG = Fasle
NameError: name 'Fasle' is not defined
[2022-11-02 14:06:56 +0300] [5541] [INFO] Worker exiting (pid: 5541)
[2022-11-02 14:06:56 +0300] [5535] [WARNING] Worker with pid 5542 was terminated due to signal 15
[2022-11-02 14:06:56 +0300] [5535] [INFO] Shutting down: Master
[2022-11-02 14:06:56 +0300] [5535] [INFO] Reason: Worker failed to boot.
[2022-11-02 14:06:57 +0300] [5544] [INFO] Starting gunicorn 20.1.0
[2022-11-02 14:06:57 +0300] [5544] [INFO] Listening at: http://127.0.0.1:8001 (5544)
[2022-11-02 14:06:57 +0300] [5544] [INFO] Using worker: sync
[2022-11-02 14:06:57 +0300] [5546] [INFO] Booting worker with pid: 5546
[2022-11-02 14:06:57 +0300] [5547] [INFO] Booting worker with pid: 5547
[2022-11-02 14:06:57 +0300] [5548] [INFO] Booting worker with pid: 5548
[2022-11-02 14:06:58 +0300] [5546] [ERROR] Exception in worker process
Traceback (most recent call last):
  File "/home/admsys/djangotest/venv/lib/python3.8/site-packages/gunicorn/arbiter.py", line 589, in spawn_worker
    worker.init_process()
  File "/home/admsys/djangotest/venv/lib/python3.8/site-packages/gunicorn/workers/base.py", line 134, in init_process
    self.load_wsgi()
  File "/home/admsys/djangotest/venv/lib/python3.8/site-packages/gunicorn/workers/base.py", line 146, in load_wsgi
    self.wsgi = self.app.wsgi()
  File "/home/admsys/djangotest/venv/lib/python3.8/site-packages/gunicorn/app/base.py", line 67, in wsgi
    self.callable = self.load()
  File "/home/admsys/djangotest/venv/lib/python3.8/site-packages/gunicorn/app/wsgiapp.py", line 58, in load
    return self.load_wsgiapp()
  File "/home/admsys/djangotest/venv/lib/python3.8/site-packages/gunicorn/app/wsgiapp.py", line 48, in load_wsgiapp
    return util.import_app(self.app_uri)
  File "/home/admsys/djangotest/venv/lib/python3.8/site-packages/gunicorn/util.py", line 359, in import_app
    mod = importlib.import_module(module)
  File "/usr/local/lib/python3.8/importlib/__init__.py", line 127, in import_module
    return _bootstrap._gcd_import(name[level:], package, level)
  File "<frozen importlib._bootstrap>", line 1014, in _gcd_import
  File "<frozen importlib._bootstrap>", line 991, in _find_and_load
  File "<frozen importlib._bootstrap>", line 975, in _find_and_load_unlocked
  File "<frozen importlib._bootstrap>", line 671, in _load_unlocked
  File "<frozen importlib._bootstrap_external>", line 848, in exec_module
  File "<frozen importlib._bootstrap>", line 219, in _call_with_frames_removed
  File "/home/admsys/djangotest/src/config/wsgi.py", line 16, in <module>
    application = get_wsgi_application()
  File "/home/admsys/djangotest/venv/lib/python3.8/site-packages/django/core/wsgi.py", line 12, in get_wsgi_application
    django.setup(set_prefix=False)
  File "/home/admsys/djangotest/venv/lib/python3.8/site-packages/django/__init__.py", line 19, in setup
    configure_logging(settings.LOGGING_CONFIG, settings.LOGGING)
  File "/home/admsys/djangotest/venv/lib/python3.8/site-packages/django/conf/__init__.py", line 92, in __getattr__
    self._setup(name)
  File "/home/admsys/djangotest/venv/lib/python3.8/site-packages/django/conf/__init__.py", line 79, in _setup
    self._wrapped = Settings(settings_module)
  File "/home/admsys/djangotest/venv/lib/python3.8/site-packages/django/conf/__init__.py", line 190, in __init__
    mod = importlib.import_module(self.SETTINGS_MODULE)
  File "/usr/local/lib/python3.8/importlib/__init__.py", line 127, in import_module
    return _bootstrap._gcd_import(name[level:], package, level)
  File "<frozen importlib._bootstrap>", line 1014, in _gcd_import
  File "<frozen importlib._bootstrap>", line 991, in _find_and_load
  File "<frozen importlib._bootstrap>", line 975, in _find_and_load_unlocked
  File "<frozen importlib._bootstrap>", line 671, in _load_unlocked
  File "<frozen importlib._bootstrap_external>", line 848, in exec_module
  File "<frozen importlib._bootstrap>", line 219, in _call_with_frames_removed
  File "/home/admsys/djangotest/src/config/settings.py", line 26, in <module>
    DEBUG = Fasle
NameError: name 'Fasle' is not defined
[2022-11-02 14:06:58 +0300] [5546] [INFO] Worker exiting (pid: 5546)
[2022-11-02 14:06:58 +0300] [5547] [ERROR] Exception in worker process
Traceback (most recent call last):
  File "/home/admsys/djangotest/venv/lib/python3.8/site-packages/gunicorn/arbiter.py", line 589, in spawn_worker
    worker.init_process()
  File "/home/admsys/djangotest/venv/lib/python3.8/site-packages/gunicorn/workers/base.py", line 134, in init_process
    self.load_wsgi()
  File "/home/admsys/djangotest/venv/lib/python3.8/site-packages/gunicorn/workers/base.py", line 146, in load_wsgi
    self.wsgi = self.app.wsgi()
  File "/home/admsys/djangotest/venv/lib/python3.8/site-packages/gunicorn/app/base.py", line 67, in wsgi
    self.callable = self.load()
  File "/home/admsys/djangotest/venv/lib/python3.8/site-packages/gunicorn/app/wsgiapp.py", line 58, in load
    return self.load_wsgiapp()
  File "/home/admsys/djangotest/venv/lib/python3.8/site-packages/gunicorn/app/wsgiapp.py", line 48, in load_wsgiapp
    return util.import_app(self.app_uri)
  File "/home/admsys/djangotest/venv/lib/python3.8/site-packages/gunicorn/util.py", line 359, in import_app
    mod = importlib.import_module(module)
  File "/usr/local/lib/python3.8/importlib/__init__.py", line 127, in import_module
    return _bootstrap._gcd_import(name[level:], package, level)
  File "<frozen importlib._bootstrap>", line 1014, in _gcd_import
  File "<frozen importlib._bootstrap>", line 991, in _find_and_load
  File "<frozen importlib._bootstrap>", line 975, in _find_and_load_unlocked
  File "<frozen importlib._bootstrap>", line 671, in _load_unlocked
  File "<frozen importlib._bootstrap_external>", line 848, in exec_module
  File "<frozen importlib._bootstrap>", line 219, in _call_with_frames_removed
  File "/home/admsys/djangotest/src/config/wsgi.py", line 16, in <module>
    application = get_wsgi_application()
  File "/home/admsys/djangotest/venv/lib/python3.8/site-packages/django/core/wsgi.py", line 12, in get_wsgi_application
    django.setup(set_prefix=False)
  File "/home/admsys/djangotest/venv/lib/python3.8/site-packages/django/__init__.py", line 19, in setup
    configure_logging(settings.LOGGING_CONFIG, settings.LOGGING)
  File "/home/admsys/djangotest/venv/lib/python3.8/site-packages/django/conf/__init__.py", line 92, in __getattr__
    self._setup(name)
  File "/home/admsys/djangotest/venv/lib/python3.8/site-packages/django/conf/__init__.py", line 79, in _setup
    self._wrapped = Settings(settings_module)
  File "/home/admsys/djangotest/venv/lib/python3.8/site-packages/django/conf/__init__.py", line 190, in __init__
    mod = importlib.import_module(self.SETTINGS_MODULE)
  File "/usr/local/lib/python3.8/importlib/__init__.py", line 127, in import_module
    return _bootstrap._gcd_import(name[level:], package, level)
  File "<frozen importlib._bootstrap>", line 1014, in _gcd_import
  File "<frozen importlib._bootstrap>", line 991, in _find_and_load
  File "<frozen importlib._bootstrap>", line 975, in _find_and_load_unlocked
  File "<frozen importlib._bootstrap>", line 671, in _load_unlocked
  File "<frozen importlib._bootstrap_external>", line 848, in exec_module
  File "<frozen importlib._bootstrap>", line 219, in _call_with_frames_removed
  File "/home/admsys/djangotest/src/config/settings.py", line 26, in <module>
    DEBUG = Fasle
NameError: name 'Fasle' is not defined
[2022-11-02 14:06:58 +0300] [5547] [INFO] Worker exiting (pid: 5547)
[2022-11-02 14:06:58 +0300] [5544] [WARNING] Worker with pid 5547 was terminated due to signal 15
[2022-11-02 14:06:58 +0300] [5548] [ERROR] Exception in worker process
Traceback (most recent call last):
  File "/home/admsys/djangotest/venv/lib/python3.8/site-packages/gunicorn/arbiter.py", line 589, in spawn_worker
    worker.init_process()
  File "/home/admsys/djangotest/venv/lib/python3.8/site-packages/gunicorn/workers/base.py", line 134, in init_process
    self.load_wsgi()
  File "/home/admsys/djangotest/venv/lib/python3.8/site-packages/gunicorn/workers/base.py", line 146, in load_wsgi
    self.wsgi = self.app.wsgi()
  File "/home/admsys/djangotest/venv/lib/python3.8/site-packages/gunicorn/app/base.py", line 67, in wsgi
    self.callable = self.load()
  File "/home/admsys/djangotest/venv/lib/python3.8/site-packages/gunicorn/app/wsgiapp.py", line 58, in load
    return self.load_wsgiapp()
  File "/home/admsys/djangotest/venv/lib/python3.8/site-packages/gunicorn/app/wsgiapp.py", line 48, in load_wsgiapp
    return util.import_app(self.app_uri)
  File "/home/admsys/djangotest/venv/lib/python3.8/site-packages/gunicorn/util.py", line 359, in import_app
    mod = importlib.import_module(module)
  File "/usr/local/lib/python3.8/importlib/__init__.py", line 127, in import_module
    return _bootstrap._gcd_import(name[level:], package, level)
  File "<frozen importlib._bootstrap>", line 1014, in _gcd_import
  File "<frozen importlib._bootstrap>", line 991, in _find_and_load
  File "<frozen importlib._bootstrap>", line 975, in _find_and_load_unlocked
  File "<frozen importlib._bootstrap>", line 671, in _load_unlocked
  File "<frozen importlib._bootstrap_external>", line 848, in exec_module
  File "<frozen importlib._bootstrap>", line 219, in _call_with_frames_removed
  File "/home/admsys/djangotest/src/config/wsgi.py", line 16, in <module>
    application = get_wsgi_application()
  File "/home/admsys/djangotest/venv/lib/python3.8/site-packages/django/core/wsgi.py", line 12, in get_wsgi_application
    django.setup(set_prefix=False)
  File "/home/admsys/djangotest/venv/lib/python3.8/site-packages/django/__init__.py", line 19, in setup
    configure_logging(settings.LOGGING_CONFIG, settings.LOGGING)
  File "/home/admsys/djangotest/venv/lib/python3.8/site-packages/django/conf/__init__.py", line 92, in __getattr__
    self._setup(name)
  File "/home/admsys/djangotest/venv/lib/python3.8/site-packages/django/conf/__init__.py", line 79, in _setup
    self._wrapped = Settings(settings_module)
  File "/home/admsys/djangotest/venv/lib/python3.8/site-packages/django/conf/__init__.py", line 190, in __init__
    mod = importlib.import_module(self.SETTINGS_MODULE)
  File "/usr/local/lib/python3.8/importlib/__init__.py", line 127, in import_module
    return _bootstrap._gcd_import(name[level:], package, level)
  File "<frozen importlib._bootstrap>", line 1014, in _gcd_import
  File "<frozen importlib._bootstrap>", line 991, in _find_and_load
  File "<frozen importlib._bootstrap>", line 975, in _find_and_load_unlocked
  File "<frozen importlib._bootstrap>", line 671, in _load_unlocked
  File "<frozen importlib._bootstrap_external>", line 848, in exec_module
  File "<frozen importlib._bootstrap>", line 219, in _call_with_frames_removed
  File "/home/admsys/djangotest/src/config/settings.py", line 26, in <module>
    DEBUG = Fasle
NameError: name 'Fasle' is not defined
[2022-11-02 14:06:58 +0300] [5548] [INFO] Worker exiting (pid: 5548)
[2022-11-02 14:07:19 +0300] [5565] [INFO] Starting gunicorn 20.1.0
[2022-11-02 14:07:19 +0300] [5565] [INFO] Listening at: http://127.0.0.1:8001 (5565)
[2022-11-02 14:07:19 +0300] [5565] [INFO] Using worker: sync
[2022-11-02 14:07:19 +0300] [5575] [INFO] Booting worker with pid: 5575
[2022-11-02 14:07:19 +0300] [5576] [INFO] Booting worker with pid: 5576
[2022-11-02 14:07:19 +0300] [5577] [INFO] Booting worker with pid: 5577
[2022-11-02 11:10:26 +0000] [5575] [INFO] Worker exiting (pid: 5575)
[2022-11-02 11:10:26 +0000] [5576] [INFO] Worker exiting (pid: 5576)
[2022-11-02 14:10:26 +0300] [5565] [INFO] Handling signal: term
[2022-11-02 11:10:26 +0000] [5577] [INFO] Worker exiting (pid: 5577)
[2022-11-02 14:10:26 +0300] [5565] [WARNING] Worker with pid 5575 was terminated due to signal 15
[2022-11-02 14:10:26 +0300] [5565] [INFO] Shutting down: Master
[2022-11-02 14:13:22 +0300] [5757] [INFO] Starting gunicorn 20.1.0
[2022-11-02 14:13:22 +0300] [5757] [INFO] Listening at: http://127.0.0.1:8001 (5757)
[2022-11-02 14:13:22 +0300] [5757] [INFO] Using worker: sync
[2022-11-02 14:13:22 +0300] [5766] [INFO] Booting worker with pid: 5766
[2022-11-02 14:13:22 +0300] [5767] [INFO] Booting worker with pid: 5767
[2022-11-02 14:13:22 +0300] [5768] [INFO] Booting worker with pid: 5768
[2022-11-02 11:19:32 +0000] [5767] [INFO] Worker exiting (pid: 5767)
[2022-11-02 14:19:32 +0300] [5757] [INFO] Handling signal: term
[2022-11-02 11:19:32 +0000] [5768] [INFO] Worker exiting (pid: 5768)
[2022-11-02 11:19:32 +0000] [5766] [INFO] Worker exiting (pid: 5766)
[2022-11-02 14:19:32 +0300] [5757] [INFO] Shutting down: Master
[2022-11-02 14:19:32 +0300] [5868] [INFO] Starting gunicorn 20.1.0
[2022-11-02 14:19:32 +0300] [5868] [INFO] Listening at: http://127.0.0.1:8001 (5868)
[2022-11-02 14:19:32 +0300] [5868] [INFO] Using worker: sync
[2022-11-02 14:19:32 +0300] [5885] [INFO] Booting worker with pid: 5885
[2022-11-02 14:19:32 +0300] [5886] [INFO] Booting worker with pid: 5886
[2022-11-02 14:19:33 +0300] [5887] [INFO] Booting worker with pid: 5887
[2022-11-02 11:20:46 +0000] [5885] [INFO] Worker exiting (pid: 5885)
[2022-11-02 11:20:46 +0000] [5886] [INFO] Worker exiting (pid: 5886)
[2022-11-02 11:20:46 +0000] [5887] [INFO] Worker exiting (pid: 5887)
[2022-11-02 14:20:46 +0300] [5868] [INFO] Handling signal: term
[2022-11-02 14:20:47 +0300] [5868] [INFO] Shutting down: Master
[2022-11-02 14:20:47 +0300] [5924] [INFO] Starting gunicorn 20.1.0
[2022-11-02 14:20:47 +0300] [5924] [INFO] Listening at: http://127.0.0.1:8001 (5924)
[2022-11-02 14:20:47 +0300] [5924] [INFO] Using worker: sync
[2022-11-02 14:20:47 +0300] [5934] [INFO] Booting worker with pid: 5934
[2022-11-02 14:20:47 +0300] [5935] [INFO] Booting worker with pid: 5935
[2022-11-02 14:20:47 +0300] [5936] [INFO] Booting worker with pid: 5936
[2022-11-02 11:21:45 +0000] [5935] [INFO] Worker exiting (pid: 5935)
[2022-11-02 11:21:45 +0000] [5936] [INFO] Worker exiting (pid: 5936)
[2022-11-02 11:21:45 +0000] [5934] [INFO] Worker exiting (pid: 5934)
[2022-11-02 14:21:45 +0300] [5924] [INFO] Handling signal: term
[2022-11-02 14:21:45 +0300] [5924] [WARNING] Worker with pid 5935 was terminated due to signal 15
[2022-11-02 14:21:45 +0300] [5924] [INFO] Shutting down: Master
[2022-11-02 14:21:46 +0300] [5964] [INFO] Starting gunicorn 20.1.0
[2022-11-02 14:21:46 +0300] [5964] [INFO] Listening at: http://127.0.0.1:8001 (5964)
[2022-11-02 14:21:46 +0300] [5964] [INFO] Using worker: sync
[2022-11-02 14:21:46 +0300] [5974] [INFO] Booting worker with pid: 5974
[2022-11-02 14:21:46 +0300] [5975] [INFO] Booting worker with pid: 5975
[2022-11-02 14:21:46 +0300] [5976] [INFO] Booting worker with pid: 5976
[2022-11-02 11:23:06 +0000] [5976] [INFO] Worker exiting (pid: 5976)
[2022-11-02 11:23:06 +0000] [5975] [INFO] Worker exiting (pid: 5975)
[2022-11-02 14:23:06 +0300] [5964] [INFO] Handling signal: term
[2022-11-02 11:23:06 +0000] [5974] [INFO] Worker exiting (pid: 5974)
[2022-11-02 14:23:06 +0300] [5964] [WARNING] Worker with pid 5975 was terminated due to signal 15
[2022-11-02 14:23:06 +0300] [5964] [WARNING] Worker with pid 5976 was terminated due to signal 15
[2022-11-02 14:23:06 +0300] [5964] [INFO] Shutting down: Master
[2022-11-02 14:23:06 +0300] [6039] [INFO] Starting gunicorn 20.1.0
[2022-11-02 14:23:06 +0300] [6039] [INFO] Listening at: http://127.0.0.1:8001 (6039)
[2022-11-02 14:23:06 +0300] [6039] [INFO] Using worker: sync
[2022-11-02 14:23:06 +0300] [6051] [INFO] Booting worker with pid: 6051
[2022-11-02 14:23:06 +0300] [6052] [INFO] Booting worker with pid: 6052
[2022-11-02 14:23:06 +0300] [6053] [INFO] Booting worker with pid: 6053
[2022-11-02 11:33:55 +0000] [6052] [INFO] Worker exiting (pid: 6052)
[2022-11-02 14:33:55 +0300] [6039] [INFO] Handling signal: term
[2022-11-02 11:33:55 +0000] [6053] [INFO] Worker exiting (pid: 6053)
[2022-11-02 11:33:55 +0000] [6051] [INFO] Worker exiting (pid: 6051)
[2022-11-02 14:33:55 +0300] [6039] [INFO] Shutting down: Master
[2022-11-02 14:33:55 +0300] [6415] [INFO] Starting gunicorn 20.1.0
[2022-11-02 14:33:55 +0300] [6415] [INFO] Listening at: http://127.0.0.1:8001 (6415)
[2022-11-02 14:33:55 +0300] [6415] [INFO] Using worker: sync
[2022-11-02 14:33:55 +0300] [6428] [INFO] Booting worker with pid: 6428
[2022-11-02 14:33:55 +0300] [6429] [INFO] Booting worker with pid: 6429
[2022-11-02 14:33:56 +0300] [6430] [INFO] Booting worker with pid: 6430
[2022-11-02 11:54:54 +0000] [6430] [INFO] Worker exiting (pid: 6430)
[2022-11-02 11:54:54 +0000] [6429] [INFO] Worker exiting (pid: 6429)
[2022-11-02 11:54:54 +0000] [6428] [INFO] Worker exiting (pid: 6428)
[2022-11-02 14:54:54 +0300] [6415] [INFO] Handling signal: term
[2022-11-02 14:54:54 +0300] [6415] [WARNING] Worker with pid 6428 was terminated due to signal 15
[2022-11-02 14:54:54 +0300] [6415] [WARNING] Worker with pid 6429 was terminated due to signal 15
[2022-11-02 14:54:54 +0300] [6415] [WARNING] Worker with pid 6430 was terminated due to signal 15
[2022-11-02 14:54:54 +0300] [6415] [INFO] Shutting down: Master
[2022-11-02 14:58:23 +0300] [7137] [INFO] Starting gunicorn 20.1.0
[2022-11-02 14:58:23 +0300] [7137] [INFO] Listening at: http://127.0.0.1:8001 (7137)
[2022-11-02 14:58:23 +0300] [7137] [INFO] Using worker: sync
[2022-11-02 14:58:23 +0300] [7148] [INFO] Booting worker with pid: 7148
[2022-11-02 14:58:23 +0300] [7149] [INFO] Booting worker with pid: 7149
[2022-11-02 14:58:23 +0300] [7150] [INFO] Booting worker with pid: 7150
